Calling variant
[13:05:30 - DataIndx] No sample_registry in Consensus/early_1_1_consensus/consensus_probs.hdf
[13:05:30 - DataIndx] No sample_registry in medaka.vcf
Traceback (most recent call last):
  File "/opt/anaconda3/envs/medaka/bin/medaka", line 8, in <module>
    sys.exit(main())
  File "/opt/anaconda3/envs/medaka/lib/python3.8/site-packages/medaka/medaka.py", line 843, in main
    args.func(args)
  File "/opt/anaconda3/envs/medaka/lib/python3.8/site-packages/medaka/variant.py", line 190, in variants_from_hdf
    index = medaka.datastore.DataIndex(args.inputs)
  File "/opt/anaconda3/envs/medaka/lib/python3.8/site-packages/medaka/datastore.py", line 423, in __init__
    self.metadata = self._load_metadata()
  File "/opt/anaconda3/envs/medaka/lib/python3.8/site-packages/medaka/datastore.py", line 465, in _load_metadata
    with DataStore(first_file) as ds:
  File "/opt/anaconda3/envs/medaka/lib/python3.8/site-packages/medaka/datastore.py", line 243, in __init__
    self.fh = h5py.File(self.filename, self.mode)
  File "/opt/anaconda3/envs/medaka/lib/python3.8/site-packages/h5py/_hl/files.py", line 562, in __init__
    fid = make_fid(name, mode, userblock_size, fapl, fcpl, swmr=swmr)
  File "/opt/anaconda3/envs/medaka/lib/python3.8/site-packages/h5py/_hl/files.py", line 235, in make_fid
    fid = h5f.open(name, flags, fapl=fapl)
  File "h5py/_objects.pyx", line 54, in h5py._objects.with_phil.wrapper
  File "h5py/_objects.pyx", line 55, in h5py._objects.with_phil.wrapper
  File "h5py/h5f.pyx", line 102, in h5py.h5f.open
FileNotFoundError: [Errno 2] Unable to synchronously open file (unable to open file: name = 'Consensus/early_1_1_consensus/consensus_probs.hdf', errno = 2, error message = 'No such file or directory', flags = 0, o_flags = 0)
